<?xml version="1.0" encoding="utf-8"?>
<!-- This URDF was automatically created by SolidWorks to URDF Exporter! Originally created by Stephen Brawner (brawner@gmail.com) 
     Commit Version: 1.6.0-4-g7f85cfe  Build Version: 1.6.7995.38578
     For more information, please see http://wiki.ros.org/sw_urdf_exporter -->
<robot
  name="wujihand-right">
  <link
    name="right_palm_link">
    <inertial><origin xyz="-0.0035258572046592 -0.0032797858267446 0.0354434824506401" rpy="0 0 0"/><mass value="0.16914"/><inertia ixx="0.00014" ixy="2.54e-06" ixz="6.91e-06" iyy="9.47e-05" iyz="-6.63e-06" izz="6e-05"/></inertial>
    <visual>
      <origin
        xyz="0 0 0"
        rpy="0 0 0" />
      <geometry>
        <mesh
          filename="package://wuji_hand_description/meshes/right/right_palm_link.STL" />
      </geometry>
      <material
        name="">
        <color
          rgba="0.627450980392157 0.627450980392157 0.627450980392157 1" />
      </material>
    </visual>
    <collision>
      <origin
        xyz="0 0 0"
        rpy="0 0 0" />
      <geometry>
        <mesh
          filename="package://wuji_hand_description/meshes/right/right_palm_link.STL" />
      </geometry>
    </collision>
  </link>
  <link
    name="right_finger1_link1">
    <inertial><origin xyz="-0.000842648531145823 0.000161376659550436 0.00756747367149346" rpy="0 0 0"/><mass value="0.0075"/><inertia ixx="3.2e-07" ixy="-2e-08" ixz="0.0" iyy="3e-07" iyz="4e-08" izz="2.3e-07"/></inertial>
    <visual>
      <origin
        xyz="0 0 0"
        rpy="0 0 0" />
      <geometry>
        <mesh
          filename="package://wuji_hand_description/meshes/right/right_finger1_link1.STL" />
      </geometry>
      <material
        name="">
        <color
          rgba="0.627450980392157 0.627450980392157 0.627450980392157 1" />
      </material>
    </visual>
    <collision>
      <origin
        xyz="0 0 0"
        rpy="0 0 0" />
      <geometry>
        <mesh
          filename="package://wuji_hand_description/meshes/right/right_finger1_link1.STL" />
      </geometry>
    </collision>
  </link>
  <joint
    name="right_finger1_joint1"
    type="revolute">
    <origin
      xyz="0.0081297 0.017208 0.016463"
      rpy="1.942 -1.0586 2.7208" />
    <parent
      link="right_palm_link" />
    <child
      link="right_finger1_link1" />
    <axis
      xyz="-1 0 0" />
    <limit
      lower="0.0368"
      upper="1.6125"
      effort="0.4452"
      velocity="8.587" />
  </joint>
  <link
    name="right_finger1_link2">
    <inertial><origin xyz="7.81312976605442e-06 1.21906809946726e-05 0.013040420107892" rpy="0 0 0"/><mass value="0.0248"/><inertia ixx="2.76e-06" ixy="2e-08" ixz="1e-08" iyy="2.81e-06" iyz="2e-08" izz="6.8e-07"/></inertial>
    <visual>
      <origin
        xyz="0 0 0"
        rpy="0 0 0" />
      <geometry>
        <mesh
          filename="package://wuji_hand_description/meshes/right/right_finger1_link2.STL" />
      </geometry>
      <material
        name="">
        <color
          rgba="0.627450980392157 0.627450980392157 0.627450980392157 1" />
      </material>
    </visual>
    <collision>
      <origin
        xyz="0 0 0"
        rpy="0 0 0" />
      <geometry>
        <mesh
          filename="package://wuji_hand_description/meshes/right/right_finger1_link2.STL" />
      </geometry>
    </collision>
  </link>
  <joint
    name="right_finger1_joint2"
    type="revolute">
    <origin
      xyz="-0.00024788 0.003574 0.014324"
      rpy="0.744 0.43559 1.6887" />
    <parent
      link="right_finger1_link1" />
    <child
      link="right_finger1_link2" />
    <axis
      xyz="1 0 0" />
    <limit
      lower="-0.1576"
      upper="0.9312"
      effort="0.4259"
      velocity="11.1" />
  </joint>
  <link
    name="right_finger1_link3">
    <inertial><origin xyz="-9.0259718255048e-08 -5.00323793714008e-05 0.0142927240855407" rpy="0 0 0"/><mass value="0.0165"/><inertia ixx="1.46e-06" ixy="0.0" ixz="-2e-08" iyy="1.42e-06" iyz="0.0" izz="4.5e-07"/></inertial>
    <visual>
      <origin
        xyz="0 0 0"
        rpy="0 0 0" />
      <geometry>
        <mesh
          filename="package://wuji_hand_description/meshes/right/right_finger1_link3.STL" />
      </geometry>
      <material
        name="">
        <color
          rgba="0.627450980392157 0.627450980392157 0.627450980392157 1" />
      </material>
    </visual>
    <collision>
      <origin
        xyz="0 0 0"
        rpy="0 0 0" />
      <geometry>
        <mesh
          filename="package://wuji_hand_description/meshes/right/right_finger1_link3.STL" />
      </geometry>
    </collision>
  </link>
  <joint
    name="right_finger1_joint3"
    type="revolute">
    <origin
      xyz="0 0 0.0325"
      rpy="0.087266 0 -0.56723" />
    <parent
      link="right_finger1_link2" />
    <child
      link="right_finger1_link3" />
    <axis
      xyz="0 1 0" />
    <limit
      lower="-0.4638"
      upper="1.5607"
      effort="0.1888"
      velocity="12.86" />
  </joint>
  <link
    name="right_finger1_link4">
    <inertial><origin xyz="-0.000586376295252378 3.43980795791676e-08 0.010882579658413" rpy="0 0 0"/><mass value="0.0165"/><inertia ixx="1.18e-06" ixy="0.0" ixz="1.2e-07" iyy="1.25e-06" iyz="0.0" izz="5.1e-07"/></inertial>
    <visual>
      <origin
        xyz="0 0 0"
        rpy="0 0 0" />
      <geometry>
        <mesh
          filename="package://wuji_hand_description/meshes/right/right_finger1_link4.STL" />
      </geometry>
      <material
        name="">
        <color
          rgba="0.627450980392157 0.627450980392157 0.627450980392157 1" />
      </material>
    </visual>
    <collision>
      <origin
        xyz="0 0 0"
        rpy="0 0 0" />
      <geometry>
        <mesh
          filename="package://wuji_hand_description/meshes/right/right_finger1_link4.STL" />
      </geometry>
    </collision>
  </link>
  <joint
    name="right_finger1_joint4"
    type="revolute">
    <origin
      xyz="0 -5E-05 0.035"
      rpy="0 0 0" />
    <parent
      link="right_finger1_link3" />
    <child
      link="right_finger1_link4" />
    <axis
      xyz="0 1 0" />
    <limit
      lower="-0.4829"
      upper="1.5451"
      effort="0.1468"
      velocity="13.5" />
  </joint>
  <link
    name="right_finger1_tip_link">
    <inertial><origin xyz="-2.8927372819898e-05 3.43980794126342e-08 -0.0168147104243449" rpy="0 0 0"/><mass value="0.0041"/><inertia ixx="5.5e-07" ixy="0.0" ixz="2e-08" iyy="5.2e-07" iyz="0.0" izz="2.7e-07"/></inertial>
    <visual>
      <origin
        xyz="0 0 0"
        rpy="0 0 0" />
      <geometry>
        <mesh
          filename="package://wuji_hand_description/meshes/right/right_finger1_tip_link.STL" />
      </geometry>
      <material
        name="">
        <color
          rgba="0.627450980392157 0.627450980392157 0.627450980392157 1" />
      </material>
    </visual>
    <collision>
      <origin
        xyz="0 0 0"
        rpy="0 0 0" />
      <geometry>
        <mesh
          filename="package://wuji_hand_description/meshes/right/right_finger1_tip_link.STL" />
      </geometry>
    </collision>
  </link>
  <joint
    name="right_finger1_tip_fixed"
    type="fixed">
    <origin
      xyz="-0.00055745 0 0.027697"
      rpy="0 0 0" />
    <parent
      link="right_finger1_link4" />
    <child
      link="right_finger1_tip_link" />
    <axis
      xyz="0 0 0" />
  </joint>
  <link
    name="right_finger2_link1">
    <inertial><origin xyz="-0.00177765095200585 -1.15178079296285e-08 0.00759979494737889" rpy="0 0 0"/><mass value="0.0032"/><inertia ixx="8e-08" ixy="0.0" ixz="-3e-08" iyy="7e-08" iyz="0.0" izz="8e-08"/></inertial>
    <visual>
      <origin
        xyz="0 0 0"
        rpy="0 0 0" />
      <geometry>
        <mesh
          filename="package://wuji_hand_description/meshes/right/right_finger2_link1.STL" />
      </geometry>
      <material
        name="">
        <color
          rgba="1 1 1 1" />
      </material>
    </visual>
    <collision>
      <origin
        xyz="0 0 0"
        rpy="0 0 0" />
      <geometry>
        <mesh
          filename="package://wuji_hand_description/meshes/right/right_finger2_link1.STL" />
      </geometry>
    </collision>
  </link>
  <joint
    name="right_finger2_joint1"
    type="revolute">
    <origin
      xyz="-0.0033601 0.022653 0.069976"
      rpy="-0.137 -0.039905 -0.094973" />
    <parent
      link="right_palm_link" />
    <child
      link="right_finger2_link1" />
    <axis
      xyz="0 1 0" />
    <limit
      lower="-0.1611"
      upper="1.5588"
      effort="0.6188"
      velocity="8.203" />
  </joint>
  <link
    name="right_finger2_link2">
    <inertial><origin xyz="4.91929306178918e-07 -7.34371052857341e-09 0.0187992452328398" rpy="0 0 0"/><mass value="0.033"/><inertia ixx="6.31e-06" ixy="0.0" ixz="-1.6e-07" iyy="6.34e-06" iyz="0.0" izz="8.9e-07"/></inertial>
    <visual>
      <origin
        xyz="0 0 0"
        rpy="0 0 0" />
      <geometry>
        <mesh
          filename="package://wuji_hand_description/meshes/right/right_finger2_link2.STL" />
      </geometry>
      <material
        name="">
        <color
          rgba="1 1 1 1" />
      </material>
    </visual>
    <collision>
      <origin
        xyz="0 0 0"
        rpy="0 0 0" />
      <geometry>
        <mesh
          filename="package://wuji_hand_description/meshes/right/right_finger2_link2.STL" />
      </geometry>
    </collision>
  </link>
  <joint
    name="right_finger2_joint2"
    type="revolute">
    <origin
      xyz="-0.001201 0 0.0145"
      rpy="0 0 0" />
    <parent
      link="right_finger2_link1" />
    <child
      link="right_finger2_link2" />
    <axis
      xyz="-1 0 0" />
    <limit
      lower="-0.4044"
      upper="0.3054"
      effort="0.1822"
      velocity="8.11" />
  </joint>
  <link
    name="right_finger2_link3">
    <inertial><origin xyz="-0.000247463406561343 2.1773383207524e-08 0.0190489353817952" rpy="0 0 0"/><mass value="0.0165"/><inertia ixx="1.47e-06" ixy="0.0" ixz="3e-08" iyy="1.44e-06" iyz="0.0" izz="4.5e-07"/></inertial>
    <visual>
      <origin
        xyz="0 0 0"
        rpy="0 0 0" />
      <geometry>
        <mesh
          filename="package://wuji_hand_description/meshes/right/right_finger2_link3.STL" />
      </geometry>
      <material
        name="">
        <color
          rgba="1 1 1 1" />
      </material>
    </visual>
    <collision>
      <origin
        xyz="0 0 0"
        rpy="0 0 0" />
      <geometry>
        <mesh
          filename="package://wuji_hand_description/meshes/right/right_finger2_link3.STL" />
      </geometry>
    </collision>
  </link>
  <joint
    name="right_finger2_joint3"
    type="revolute">
    <origin
      xyz="0 0 0.0376000000000015"
      rpy="0 0 0" />
    <parent
      link="right_finger2_link2" />
    <child
      link="right_finger2_link3" />
    <axis
      xyz="0 1 0" />
    <limit
      lower="-0.4714"
      upper="1.5504"
      effort="0.2251"
      velocity="12.86" />
  </joint>
  <link
    name="right_finger2_link4">
    <inertial><origin xyz="-0.000663999328339437 2.67040356494164e-09 0.0119913025777885" rpy="0 0 0"/><mass value="0.014"/><inertia ixx="9.5e-07" ixy="0.0" ixz="1.4e-07" iyy="8.6e-07" iyz="-1e-08" izz="3e-07"/></inertial>
    <visual>
      <origin
        xyz="0 0 0"
        rpy="0 0 0" />
      <geometry>
        <mesh
          filename="package://wuji_hand_description/meshes/right/right_finger2_link4.STL" />
      </geometry>
      <material
        name="">
        <color
          rgba="1 1 1 1" />
      </material>
    </visual>
    <collision>
      <origin
        xyz="0 0 0"
        rpy="0 0 0" />
      <geometry>
        <mesh
          filename="package://wuji_hand_description/meshes/right/right_finger2_link4.STL" />
      </geometry>
    </collision>
  </link>
  <joint
    name="right_finger2_joint4"
    type="revolute">
    <origin
      xyz="0 0 0.0295"
      rpy="0 0 0" />
    <parent
      link="right_finger2_link3" />
    <child
      link="right_finger2_link4" />
    <axis
      xyz="0 1 0" />
    <limit
      lower="-0.4644"
      upper="1.5753"
      effort="0.2170"
      velocity="13.5" />
  </joint>
  <link
    name="right_finger2_tip_link">
    <inertial><origin xyz="0.00100819813927806 2.66985344943294e-09 -0.0130086974222116" rpy="0 0 0"/><mass value="0.00318"/><inertia ixx="2e-07" ixy="0.0" ixz="0.0" iyy="2.1e-07" iyz="0.0" izz="1.3e-07"/></inertial>
    <visual>
      <origin
        xyz="0 0 0"
        rpy="0 0 0" />
      <geometry>
        <mesh
          filename="package://wuji_hand_description/meshes/right/right_finger2_tip_link.STL" />
      </geometry>
      <material
        name="">
        <color
          rgba="1 1 1 1" />
      </material>
    </visual>
    <collision>
      <origin
        xyz="0 0 0"
        rpy="0 0 0" />
      <geometry>
        <mesh
          filename="package://wuji_hand_description/meshes/right/right_finger2_tip_link.STL" />
      </geometry>
    </collision>
  </link>
  <joint
    name="right_finger2_tip_fixed"
    type="fixed">
    <origin
      xyz="-0.00167219746761749 0 0.0250000000000001"
      rpy="0 0 0" />
    <parent
      link="right_finger2_link4" />
    <child
      link="right_finger2_tip_link" />
    <axis
      xyz="0 0 0" />
  </joint>
  <link
    name="right_finger3_link1">
    <inertial><origin xyz="-0.00177764391512435 -1.12854319223032e-08 0.00759979906510892" rpy="0 0 0"/><mass value="0.0032"/><inertia ixx="8e-08" ixy="0.0" ixz="-3e-08" iyy="7e-08" iyz="0.0" izz="8e-08"/></inertial>
    <visual>
      <origin
        xyz="0 0 0"
        rpy="0 0 0" />
      <geometry>
        <mesh
          filename="package://wuji_hand_description/meshes/right/right_finger3_link1.STL" />
      </geometry>
      <material
        name="">
        <color
          rgba="1 1 1 1" />
      </material>
    </visual>
    <collision>
      <origin
        xyz="0 0 0"
        rpy="0 0 0" />
      <geometry>
        <mesh
          filename="package://wuji_hand_description/meshes/right/right_finger3_link1.STL" />
      </geometry>
    </collision>
  </link>
  <joint
    name="right_finger3_joint1"
    type="revolute">
    <origin
      xyz="-0.0083399 0.00094389 0.073911"
      rpy="0.011153 -0.034411 0.00033712" />
    <parent
      link="right_palm_link" />
    <child
      link="right_finger3_link1" />
    <axis
      xyz="0 1 0" />
    <limit
      lower="-0.1719"
      upper="1.5496"
      effort="0.6494"
      velocity="8.203" />
  </joint>
  <link
    name="right_finger3_link2">
    <inertial><origin xyz="4.92493406623008e-07 -8.86716777781515e-09 0.0187992452671336" rpy="0 0 0"/><mass value="0.033"/><inertia ixx="6.31e-06" ixy="0.0" ixz="-1.6e-07" iyy="6.34e-06" iyz="0.0" izz="8.9e-07"/></inertial>
    <visual>
      <origin
        xyz="0 0 0"
        rpy="0 0 0" />
      <geometry>
        <mesh
          filename="package://wuji_hand_description/meshes/right/right_finger3_link2.STL" />
      </geometry>
      <material
        name="">
        <color
          rgba="1 1 1 1" />
      </material>
    </visual>
    <collision>
      <origin
        xyz="0 0 0"
        rpy="0 0 0" />
      <geometry>
        <mesh
          filename="package://wuji_hand_description/meshes/right/right_finger3_link2.STL" />
      </geometry>
    </collision>
  </link>
  <joint
    name="right_finger3_joint2"
    type="revolute">
    <origin
      xyz="-0.00120098018725689 0 0.0145000000001074"
      rpy="0 0 0" />
    <parent
      link="right_finger3_link1" />
    <child
      link="right_finger3_link2" />
    <axis
      xyz="-1 0 0" />
    <limit
      lower="-0.4014"
      upper="0.2996"
      effort="0.1827"
      velocity="8.11" />
  </joint>
  <link
    name="right_finger3_link3">
    <inertial><origin xyz="-0.000247480394115683 7.55122702145172e-08 0.0190489213049141" rpy="0 0 0"/><mass value="0.0165"/><inertia ixx="1.47e-06" ixy="0.0" ixz="3e-08" iyy="1.44e-06" iyz="0.0" izz="4.5e-07"/></inertial>
    <visual>
      <origin
        xyz="0 0 0"
        rpy="0 0 0" />
      <geometry>
        <mesh
          filename="package://wuji_hand_description/meshes/right/right_finger3_link3.STL" />
      </geometry>
      <material
        name="">
        <color
          rgba="1 1 1 1" />
      </material>
    </visual>
    <collision>
      <origin
        xyz="0 0 0"
        rpy="0 0 0" />
      <geometry>
        <mesh
          filename="package://wuji_hand_description/meshes/right/right_finger3_link3.STL" />
      </geometry>
    </collision>
  </link>
  <joint
    name="right_finger3_joint3"
    type="revolute">
    <origin
      xyz="0 0 0.0376"
      rpy="0 0 0" />
    <parent
      link="right_finger3_link2" />
    <child
      link="right_finger3_link3" />
    <axis
      xyz="0 1 0" />
    <limit
      lower="-0.4632"
      upper="1.5613"
      effort="0.2078"
      velocity="12.86" />
  </joint>
  <link
    name="right_finger3_link4">
    <inertial><origin xyz="-0.00066398730386729 1.13299939430433e-08 0.0119913138314083" rpy="0 0 0"/><mass value="0.014"/><inertia ixx="9.5e-07" ixy="0.0" ixz="1.4e-07" iyy="8.6e-07" iyz="-1e-08" izz="3e-07"/></inertial>
    <visual>
      <origin
        xyz="0 0 0"
        rpy="0 0 0" />
      <geometry>
        <mesh
          filename="package://wuji_hand_description/meshes/right/right_finger3_link4.STL" />
      </geometry>
      <material
        name="">
        <color
          rgba="1 1 1 1" />
      </material>
    </visual>
    <collision>
      <origin
        xyz="0 0 0"
        rpy="0 0 0" />
      <geometry>
        <mesh
          filename="package://wuji_hand_description/meshes/right/right_finger3_link4.STL" />
      </geometry>
    </collision>
  </link>
  <joint
    name="right_finger3_joint4"
    type="revolute">
    <origin
      xyz="0 0 0.0295"
      rpy="0 0 0" />
    <parent
      link="right_finger3_link3" />
    <child
      link="right_finger3_link4" />
    <axis
      xyz="0 1 0" />
    <limit
      lower="-0.4697"
      upper="1.5702"
      effort="0.2018"
      velocity="13.5" />
  </joint>
  <link
    name="right_finger3_tip_link">
    <inertial><origin xyz="1.87607255630606e-06 -0.001008208418319 -0.0130086861685918" rpy="0 0 0"/><mass value="0.00318"/><inertia ixx="2e-07" ixy="0.0" ixz="0.0" iyy="2.1e-07" iyz="0.0" izz="1.3e-07"/></inertial>
    <visual>
      <origin
        xyz="0 0 0"
        rpy="0 0 0" />
      <geometry>
        <mesh
          filename="package://wuji_hand_description/meshes/right/right_finger3_tip_link.STL" />
      </geometry>
      <material
        name="">
        <color
          rgba="1 1 1 1" />
      </material>
    </visual>
    <collision>
      <origin
        xyz="0 0 0"
        rpy="0 0 0" />
      <geometry>
        <mesh
          filename="package://wuji_hand_description/meshes/right/right_finger3_tip_link.STL" />
      </geometry>
    </collision>
  </link>
  <joint
    name="right_finger3_tip_fixed"
    type="fixed">
    <origin
      xyz="-0.0016722 0 0.025"
      rpy="0 0 1.5689" />
    <parent
      link="right_finger3_link4" />
    <child
      link="right_finger3_tip_link" />
    <axis
      xyz="0 0 0" />
  </joint>
  <link
    name="right_finger4_link1">
    <inertial><origin xyz="-0.00177765263463801 -1.22072292274567e-08 0.00759979370051524" rpy="0 0 0"/><mass value="0.0032"/><inertia ixx="8e-08" ixy="0.0" ixz="-3e-08" iyy="7e-08" iyz="0.0" izz="8e-08"/></inertial>
    <visual>
      <origin
        xyz="0 0 0"
        rpy="0 0 0" />
      <geometry>
        <mesh
          filename="package://wuji_hand_description/meshes/right/right_finger4_link1.STL" />
      </geometry>
      <material
        name="">
        <color
          rgba="1 1 1 1" />
      </material>
    </visual>
    <collision>
      <origin
        xyz="0 0 0"
        rpy="0 0 0" />
      <geometry>
        <mesh
          filename="package://wuji_hand_description/meshes/right/right_finger4_link1.STL" />
      </geometry>
    </collision>
  </link>
  <joint
    name="right_finger4_joint1"
    type="revolute">
    <origin
      xyz="-0.0056256 -0.019751 0.065395"
      rpy="0.14173 -0.016994 0.065967" />
    <parent
      link="right_palm_link" />
    <child
      link="right_finger4_link1" />
    <axis
      xyz="0 1 0" />
    <limit
      lower="-0.1601"
      upper="1.5534"
      effort="0.6389"
      velocity="8.203" />
  </joint>
  <link
    name="right_finger4_link2">
    <inertial><origin xyz="4.93473778534481e-07 -9.58545143259215e-09 0.0187992457181845" rpy="0 0 0"/><mass value="0.033"/><inertia ixx="6.31e-06" ixy="0.0" ixz="-1.6e-07" iyy="6.34e-06" iyz="0.0" izz="8.9e-07"/></inertial>
    <visual>
      <origin
        xyz="0 0 0"
        rpy="0 0 0" />
      <geometry>
        <mesh
          filename="package://wuji_hand_description/meshes/right/right_finger4_link2.STL" />
      </geometry>
      <material
        name="">
        <color
          rgba="1 1 1 1" />
      </material>
    </visual>
    <collision>
      <origin
        xyz="0 0 0"
        rpy="0 0 0" />
      <geometry>
        <mesh
          filename="package://wuji_hand_description/meshes/right/right_finger4_link2.STL" />
      </geometry>
    </collision>
  </link>
  <joint
    name="right_finger4_joint2"
    type="revolute">
    <origin
      xyz="-0.001201 0 0.0145"
      rpy="0 0 0" />
    <parent
      link="right_finger4_link1" />
    <child
      link="right_finger4_link2" />
    <axis
      xyz="-1 0 0" />
    <limit
      lower="-0.4134"
      upper="0.3161"
      effort="0.1832"
      velocity="8.11" />
  </joint>
  <link
    name="right_finger4_link3">
    <inertial><origin xyz="-0.000247474638218642 4.60224632847783e-08 0.0190489132120298" rpy="0 0 0"/><mass value="0.0165"/><inertia ixx="1.47e-06" ixy="0.0" ixz="3e-08" iyy="1.44e-06" iyz="0.0" izz="4.5e-07"/></inertial>
    <visual>
      <origin
        xyz="0 0 0"
        rpy="0 0 0" />
      <geometry>
        <mesh
          filename="package://wuji_hand_description/meshes/right/right_finger4_link3.STL" />
      </geometry>
      <material
        name="">
        <color
          rgba="1 1 1 1" />
      </material>
    </visual>
    <collision>
      <origin
        xyz="0 0 0"
        rpy="0 0 0" />
      <geometry>
        <mesh
          filename="package://wuji_hand_description/meshes/right/right_finger4_link3.STL" />
      </geometry>
    </collision>
  </link>
  <joint
    name="right_finger4_joint3"
    type="revolute">
    <origin
      xyz="0 0 0.0376000000000015"
      rpy="0 0 0" />
    <parent
      link="right_finger4_link2" />
    <child
      link="right_finger4_link3" />
    <axis
      xyz="0 1 0" />
    <limit
      lower="-0.4782"
      upper="1.5448"
      effort="0.2249"
      velocity="12.86" />
  </joint>
  <link
    name="right_finger4_link4">
    <inertial><origin xyz="-0.000663997902322272 1.9566521847203e-08 0.0119913185488839" rpy="0 0 0"/><mass value="0.014"/><inertia ixx="9.5e-07" ixy="0.0" ixz="1.4e-07" iyy="8.6e-07" iyz="-1e-08" izz="3e-07"/></inertial>
    <visual>
      <origin
        xyz="0 0 0"
        rpy="0 0 0" />
      <geometry>
        <mesh
          filename="package://wuji_hand_description/meshes/right/right_finger4_link4.STL" />
      </geometry>
      <material
        name="">
        <color
          rgba="1 1 1 1" />
      </material>
    </visual>
    <collision>
      <origin
        xyz="0 0 0"
        rpy="0 0 0" />
      <geometry>
        <mesh
          filename="package://wuji_hand_description/meshes/right/right_finger4_link4.STL" />
      </geometry>
    </collision>
  </link>
  <joint
    name="right_finger4_joint4"
    type="revolute">
    <origin
      xyz="0 0 0.0295"
      rpy="0 0 0" />
    <parent
      link="right_finger4_link3" />
    <child
      link="right_finger4_link4" />
    <axis
      xyz="0 1 0" />
    <limit
      lower="-0.4825"
      upper="1.5550"
      effort="0.2044"
      velocity="13.5" />
  </joint>
  <link
    name="right_finger4_tip_link">
    <inertial><origin xyz="-0.000294512043976458 0.000964224569173111 -0.0130086814511161" rpy="0 0 0"/><mass value="0.00318"/><inertia ixx="2e-07" ixy="0.0" ixz="0.0" iyy="2.1e-07" iyz="0.0" izz="1.3e-07"/></inertial>
    <visual>
      <origin
        xyz="0 0 0"
        rpy="0 0 0" />
      <geometry>
        <mesh
          filename="package://wuji_hand_description/meshes/right/right_finger4_tip_link.STL" />
      </geometry>
      <material
        name="">
        <color
          rgba="1 1 1 1" />
      </material>
    </visual>
    <collision>
      <origin
        xyz="0 0 0"
        rpy="0 0 0" />
      <geometry>
        <mesh
          filename="package://wuji_hand_description/meshes/right/right_finger4_tip_link.STL" />
      </geometry>
    </collision>
  </link>
  <joint
    name="right_finger4_tip_fixed"
    type="fixed">
    <origin
      xyz="-0.00167219746761747 0 0.025"
      rpy="0 0 -1.8672163655129" />
    <parent
      link="right_finger4_link4" />
    <child
      link="right_finger4_tip_link" />
    <axis
      xyz="0 0 0" />
  </joint>
  <link
    name="right_finger5_link1">
    <inertial><origin xyz="-0.001777657305092 -1.11187843376825e-08 0.00759979060747737" rpy="0 0 0"/><mass value="0.0032"/><inertia ixx="8e-08" ixy="0.0" ixz="-3e-08" iyy="7e-08" iyz="0.0" izz="8e-08"/></inertial>
    <visual>
      <origin
        xyz="0 0 0"
        rpy="0 0 0" />
      <geometry>
        <mesh
          filename="package://wuji_hand_description/meshes/right/right_finger5_link1.STL" />
      </geometry>
      <material
        name="">
        <color
          rgba="1 1 1 1" />
      </material>
    </visual>
    <collision>
      <origin
        xyz="0 0 0"
        rpy="0 0 0" />
      <geometry>
        <mesh
          filename="package://wuji_hand_description/meshes/right/right_finger5_link1.STL" />
      </geometry>
    </collision>
  </link>
  <joint
    name="right_finger5_joint1"
    type="revolute">
    <origin
      xyz="-0.000761381007086758 -0.0373566917530012 0.0552917300142485"
      rpy="0.248910111063835 -0.0100079660367069 0.133606798058913" />
    <parent
      link="right_palm_link" />
    <child
      link="right_finger5_link1" />
    <axis
      xyz="0 1 0" />
    <limit
      lower="-0.1674"
      upper="1.5539"
      effort="0.6441"
      velocity="8.203" />
  </joint>
  <link
    name="right_finger5_link2">
    <inertial><origin xyz="2.44475296673485e-07 0.000177980357365159 0.0167857210953326" rpy="0 0 0"/><mass value="0.033"/><inertia ixx="6.31e-06" ixy="0.0" ixz="-1.6e-07" iyy="6.34e-06" iyz="0.0" izz="8.9e-07"/></inertial>
    <visual>
      <origin
        xyz="0 0 0"
        rpy="0 0 0" />
      <geometry>
        <mesh
          filename="package://wuji_hand_description/meshes/right/right_finger5_link2.STL" />
      </geometry>
      <material
        name="">
        <color
          rgba="1 1 1 1" />
      </material>
    </visual>
    <collision>
      <origin
        xyz="0 0 0"
        rpy="0 0 0" />
      <geometry>
        <mesh
          filename="package://wuji_hand_description/meshes/right/right_finger5_link2.STL" />
      </geometry>
    </collision>
  </link>
  <joint
    name="right_finger5_joint2"
    type="revolute">
    <origin
      xyz="-0.00120098018724168 0 0.0145000000001571"
      rpy="0.0106031882018288 0 0" />
    <parent
      link="right_finger5_link1" />
    <child
      link="right_finger5_link2" />
    <axis
      xyz="-1 0 0" />
    <limit
      lower="-0.4203"
      upper="0.2931"
      effort="0.1798"
      velocity="8.11" />
  </joint>
  <link
    name="right_finger5_link3">
    <inertial><origin xyz="-0.000264215084761127 2.96027994339809e-08 0.017897360085972" rpy="0 0 0"/><mass value="0.0165"/><inertia ixx="1.47e-06" ixy="0.0" ixz="3e-08" iyy="1.44e-06" iyz="0.0" izz="4.5e-07"/></inertial>
    <visual>
      <origin
        xyz="0 0 0"
        rpy="0 0 0" />
      <geometry>
        <mesh
          filename="package://wuji_hand_description/meshes/right/right_finger5_link3.STL" />
      </geometry>
      <material
        name="">
        <color
          rgba="1 1 1 1" />
      </material>
    </visual>
    <collision>
      <origin
        xyz="0 0 0"
        rpy="0 0 0" />
      <geometry>
        <mesh
          filename="package://wuji_hand_description/meshes/right/right_finger5_link3.STL" />
      </geometry>
    </collision>
  </link>
  <joint
    name="right_finger5_joint3"
    type="revolute">
    <origin
      xyz="0 0.000456254826584512 0.0335970509350638"
      rpy="-0.0106031882018287 0 0" />
    <parent
      link="right_finger5_link2" />
    <child
      link="right_finger5_link3" />
    <axis
      xyz="0 1 0" />
    <limit
      lower="-0.4804"
      upper="1.5420"
      effort="0.2384"
      velocity="12.86" />
  </joint>
  <link
    name="right_finger5_link4">
    <inertial><origin xyz="-0.000570504511217762 3.44238049176937e-08 0.0121005087035554" rpy="0 0 0"/><mass value="0.014"/><inertia ixx="9.5e-07" ixy="0.0" ixz="1.4e-07" iyy="8.6e-07" iyz="-1e-08" izz="3e-07"/></inertial>
    <visual>
      <origin
        xyz="0 0 0"
        rpy="0 0 0" />
      <geometry>
        <mesh
          filename="package://wuji_hand_description/meshes/right/right_finger5_link4.STL" />
      </geometry>
      <material
        name="">
        <color
          rgba="1 1 1 1" />
      </material>
    </visual>
    <collision>
      <origin
        xyz="0 0 0"
        rpy="0 0 0" />
      <geometry>
        <mesh
          filename="package://wuji_hand_description/meshes/right/right_finger5_link4.STL" />
      </geometry>
    </collision>
  </link>
  <joint
    name="right_finger5_joint4"
    type="revolute">
    <origin
      xyz="0 0 0.0275000000000001"
      rpy="0 0 0" />
    <parent
      link="right_finger5_link3" />
    <child
      link="right_finger5_link4" />
    <axis
      xyz="0 1 0" />
    <limit
      lower="-0.4705"
      upper="1.5709"
      effort="0.1866"
      velocity="13.5" />
  </joint>
  <link
    name="right_finger5_tip_link">
    <inertial><origin xyz="0.00110169295639981 3.44338668689659e-08 -0.0128994912964446" rpy="0 0 0"/><mass value="0.00318"/><inertia ixx="2e-07" ixy="0.0" ixz="0.0" iyy="2.1e-07" iyz="0.0" izz="1.3e-07"/></inertial>
    <visual>
      <origin
        xyz="0 0 0"
        rpy="0 0 0" />
      <geometry>
        <mesh
          filename="package://wuji_hand_description/meshes/right/right_finger5_tip_link.STL" />
      </geometry>
      <material
        name="">
        <color
          rgba="1 1 1 1" />
      </material>
    </visual>
    <collision>
      <origin
        xyz="0 0 0"
        rpy="0 0 0" />
      <geometry>
        <mesh
          filename="package://wuji_hand_description/meshes/right/right_finger5_tip_link.STL" />
      </geometry>
    </collision>
  </link>
  <joint
    name="right_finger5_tip_fixed"
    type="fixed">
    <origin
      xyz="-0.00167219746761757 0 0.025"
      rpy="0 0 0" />
    <parent
      link="right_finger5_link4" />
    <child
      link="right_finger5_tip_link" />
    <axis
      xyz="0 0 0" />
  </joint>
</robot>