<mujoco model="wujihand-right-v1.0.2">
  <compiler angle="radian" meshdir="../meshes/right/" />


  <option jacobian="sparse" 
          integrator="RK4" 
          timestep="0.002" 
          solver="Newton" 
          iterations="50" 
          tolerance="1e-10" 
          impratio="10"/>

  <default>
    <joint armature="0.005" damping="0.05" frictionloss="0.01"/>
  </default>
  <asset>
    <mesh name="right_palm_link" content_type="model/stl" file="right_palm_link.STL" />
    <mesh name="right_palm_link_collision" content_type="model/stl" file="right_palm_link_collision.STL" />
    <mesh name="right_finger1_link1" content_type="model/stl" file="right_finger1_link1.STL" />
    <mesh name="right_finger1_link1_collision" content_type="model/stl" file="right_finger1_link1_collision.STL" />
    <mesh name="right_finger1_link2" content_type="model/stl" file="right_finger1_link2.STL" />
    <mesh name="right_finger1_link2_collision" content_type="model/stl" file="right_finger1_link2_collision.STL" />
    <mesh name="right_finger1_link3" content_type="model/stl" file="right_finger1_link3.STL" />
    <mesh name="right_finger1_link3_collision" content_type="model/stl" file="right_finger1_link3_collision.STL" />
    <mesh name="right_finger1_link4" content_type="model/stl" file="right_finger1_link4.STL" />
    <mesh name="right_finger1_link4_collision" content_type="model/stl" file="right_finger1_link4_collision.STL" />
    <mesh name="right_finger1_tip_link" content_type="model/stl" file="right_finger1_tip_link.STL" />
    <mesh name="right_finger1_tip_link_collision" content_type="model/stl" file="right_finger1_tip_link_collision.STL" />
    <mesh name="right_finger2_link1" content_type="model/stl" file="right_finger2_link1.STL" />
    <mesh name="right_finger2_link1_collision" content_type="model/stl" file="right_finger2_link1_collision.STL" />
    <mesh name="right_finger2_link2" content_type="model/stl" file="right_finger2_link2.STL" />
    <mesh name="right_finger2_link2_collision" content_type="model/stl" file="right_finger2_link2_collision.STL" />
    <mesh name="right_finger2_link3" content_type="model/stl" file="right_finger2_link3.STL" />
    <mesh name="right_finger2_link3_collision" content_type="model/stl" file="right_finger2_link3_collision.STL" />
    <mesh name="right_finger2_link4" content_type="model/stl" file="right_finger2_link4.STL" />
    <mesh name="right_finger2_link4_collision" content_type="model/stl" file="right_finger2_link4_collision.STL" />
    <mesh name="right_finger2_tip_link" content_type="model/stl" file="right_finger2_tip_link.STL" />
    <mesh name="right_finger2_tip_link_collision" content_type="model/stl" file="right_finger2_tip_link_collision.STL" />
    <mesh name="right_finger3_link1" content_type="model/stl" file="right_finger3_link1.STL" />
    <mesh name="right_finger3_link1_collision" content_type="model/stl" file="right_finger3_link1_collision.STL" />
    <mesh name="right_finger3_link2" content_type="model/stl" file="right_finger3_link2.STL" />
    <mesh name="right_finger3_link2_collision" content_type="model/stl" file="right_finger3_link2_collision.STL" />
    <mesh name="right_finger3_link3" content_type="model/stl" file="right_finger3_link3.STL" />
    <mesh name="right_finger3_link3_collision" content_type="model/stl" file="right_finger3_link3_collision.STL" />
    <mesh name="right_finger3_link4" content_type="model/stl" file="right_finger3_link4.STL" />
    <mesh name="right_finger3_link4_collision" content_type="model/stl" file="right_finger3_link4_collision.STL" />
    <mesh name="right_finger3_tip_link" content_type="model/stl" file="right_finger3_tip_link.STL" />
    <mesh name="right_finger3_tip_link_collision" content_type="model/stl" file="right_finger3_tip_link_collision.STL" />
    <mesh name="right_finger4_link1" content_type="model/stl" file="right_finger4_link1.STL" />
    <mesh name="right_finger4_link1_collision" content_type="model/stl" file="right_finger4_link1_collision.STL" />
    <mesh name="right_finger4_link2" content_type="model/stl" file="right_finger4_link2.STL" />
    <mesh name="right_finger4_link2_collision" content_type="model/stl" file="right_finger4_link2_collision.STL" />
    <mesh name="right_finger4_link3" content_type="model/stl" file="right_finger4_link3.STL" />
    <mesh name="right_finger4_link3_collision" content_type="model/stl" file="right_finger4_link3_collision.STL" />
    <mesh name="right_finger4_link4" content_type="model/stl" file="right_finger4_link4.STL" />
    <mesh name="right_finger4_link4_collision" content_type="model/stl" file="right_finger4_link4_collision.STL" />
    <mesh name="right_finger4_tip_link" content_type="model/stl" file="right_finger4_tip_link.STL" />
    <mesh name="right_finger4_tip_link_collision" content_type="model/stl" file="right_finger4_tip_link_collision.STL" />
    <mesh name="right_finger5_link1" content_type="model/stl" file="right_finger5_link1.STL" />
    <mesh name="right_finger5_link1_collision" content_type="model/stl" file="right_finger5_link1_collision.STL" />
    <mesh name="right_finger5_link2" content_type="model/stl" file="right_finger5_link2.STL" />
    <mesh name="right_finger5_link2_collision" content_type="model/stl" file="right_finger5_link2_collision.STL" />
    <mesh name="right_finger5_link3" content_type="model/stl" file="right_finger5_link3.STL" />
    <mesh name="right_finger5_link3_collision" content_type="model/stl" file="right_finger5_link3_collision.STL" />
    <mesh name="right_finger5_link4" content_type="model/stl" file="right_finger5_link4.STL" />
    <mesh name="right_finger5_link4_collision" content_type="model/stl" file="right_finger5_link4_collision.STL" />
    <mesh name="right_finger5_tip_link" content_type="model/stl" file="right_finger5_tip_link.STL" />
    <mesh name="right_finger5_tip_link_collision" content_type="model/stl" file="right_finger5_tip_link_collision.STL" />
  </asset>

  <worldbody>
    <geom type="mesh" contype="0" conaffinity="0" group="1" density="0" rgba="0.6 0.8 0.9 1" mesh="right_palm_link" />
    <geom type="mesh" rgba="0.6 0.8 0.9 1" mesh="right_palm_link_collision" contype="1" conaffinity="1" />
    <body name="right_finger1_link1" pos="0.0085244 0.020575 0.028712" quat="0.682219 -0.617669 0.0805047 -0.382859">
      <inertial pos="-0.0024628 -0.0014428 0.0077802" quat="0.904243 0.21652 0.0443878 -0.365368" mass="0.0075" diaginertia="3.37599e-07 3.01198e-07 2.11203e-07" />
      <joint name="right_finger1_joint1" pos="0 0 0" axis="0 1 0" range="0.0368 1.6125" actuatorfrcrange="-0.4452 0.4452" />
      <geom type="mesh" contype="0" conaffinity="0" group="1" density="0" rgba="0.7 0.7 0.7 1" mesh="right_finger1_link1" />
      <geom type="mesh" rgba="0.7 0.7 0.7 1" mesh="right_finger1_link1_collision" contype="0" conaffinity="0" />
      <body name="right_finger1_link2" pos="-0.0047549 -0.0060191 0.014132" quat="0.616955 -0.0855901 -0.290851 0.726255">
        <inertial pos="0.0011196 -1.2405e-05 0.015663" quat="0.815906 0.0024483 -0.00462559 0.57816" mass="0.0248" diaginertia="2.81725e-06 2.75299e-06 6.79766e-07" />
        <joint name="right_finger1_joint2" pos="0 0 0" axis="0 -1 0" range="-0.1576 0.9312" actuatorfrcrange="-0.4259 0.4259" />
        <geom type="mesh" contype="0" conaffinity="0" group="1" density="0" rgba="0.9 0.8 0.6 1" mesh="right_finger1_link2" />
        <geom type="mesh" rgba="0.9 0.8 0.6 1" mesh="right_finger1_link2_collision" contype="2" conaffinity="2" />
        <body name="right_finger1_link3" pos="0.00018873 -0.0009916 0.034664" quat="0.577852 0.0212383 -0.0150031 -0.815727">
          <inertial pos="-0.0011235 -1.579e-05 0.013056" quat="0.999951 0 0.00989566 0" mass="0.0165" diaginertia="1.4604e-06 1.42e-06 4.49604e-07" />
          <joint name="right_finger1_joint3" pos="0 0 0" axis="0 1 0" range="-0.4638 1.5607" actuatorfrcrange="-0.1888 0.1888" />
          <geom type="mesh" contype="0" conaffinity="0" group="1" density="0" rgba="0.6 0.8 0.9 1" mesh="right_finger1_link3" />
          <geom type="mesh" rgba="0.6 0.8 0.9 1" mesh="right_finger1_link3_collision" contype="1" conaffinity="1" />
          <body name="right_finger1_link4" pos="0 -0.00025 0.0295">
            <inertial pos="-0.00160983 0.000234366 0.0113487" quat="0.705453 -0.0487835 -0.0489426 0.705379" mass="0.0206" diaginertia="2.60023e-06 2.58038e-06 7.59852e-07" />
            <joint name="right_finger1_joint4" pos="0 0 0" axis="0 1 0" range="-0.4829 1.5451" actuatorfrcrange="-0.1468 0.1468" />
            <geom type="mesh" contype="0" conaffinity="0" group="1" density="0" rgba="0.6 0.8 0.9 1" mesh="right_finger1_link4" />
            <geom type="mesh" rgba="0.6 0.8 0.9 1" mesh="right_finger1_link4_collision" contype="1" conaffinity="1" />
            <geom pos="-0.0011048 0.00023218 0.0283" type="mesh" contype="0" conaffinity="0" group="1" density="0" rgba="0.6 0.8 0.9 1" mesh="right_finger1_tip_link" />
            <geom pos="-0.0011048 0.00023218 0.0283" type="mesh" rgba="0.6 0.8 0.9 1" mesh="right_finger1_tip_link_collision" contype="1" conaffinity="1" />
          </body>
        </body>
      </body>
    </body>
    <body name="right_finger2_link1" pos="-0.0058701 0.029434 0.091917" quat="0.991689 -0.0588295 -0.0292755 -0.110614">
      <inertial pos="-0.0013291 -3.2911e-08 0.00031987" quat="0.92388 0 0.382683 0" mass="0.0032" diaginertia="1.1e-07 7e-08 5e-08" />
      <joint name="right_finger2_joint1" pos="0 0 0" axis="0 1 0" range="-0.1611 1.5588" actuatorfrcrange="-0.6188 0.6188" />
      <geom type="mesh" contype="0" conaffinity="0" group="1" density="0" rgba="0.7 0.7 0.7 1" mesh="right_finger2_link1" />
      <geom type="mesh" rgba="0.7 0.7 0.7 1" mesh="right_finger2_link1_collision" contype="0" conaffinity="0" />
      <body name="right_finger2_link2" pos="0.0022 0 0.004">
        <inertial pos="-0.0061577 -4.1189e-07 0.020911" quat="0.70703 0.0104245 0.0104245 0.70703" mass="0.033" diaginertia="6.34e-06 6.31472e-06 8.85281e-07" />
        <joint name="right_finger2_joint2" pos="0 0 0" axis="-1 0 0" range="-0.4044 0.3054" actuatorfrcrange="-0.1822 0.1822" />
        <geom type="mesh" contype="0" conaffinity="0" group="1" density="0" rgba="0.9 0.8 0.6 1" mesh="right_finger2_link2" />
        <geom type="mesh" rgba="0.9 0.8 0.6 1" mesh="right_finger2_link2_collision" contype="2" conaffinity="2" />
        <body name="right_finger2_link3" pos="-0.0047503 0 0.043618" quat="1 0 0 -0.000134305">
          <inertial pos="-0.0011668 4.1873e-06 0.026893" quat="0.999892 0 -0.0146884 0" mass="0.0165" diaginertia="1.47088e-06 1.44e-06 4.49118e-07" />
          <joint name="right_finger2_joint3" pos="0 0 0" axis="0 1 0" range="-0.4714 1.5504" actuatorfrcrange="-0.2251 0.2251" />
          <geom type="mesh" contype="0" conaffinity="0" group="1" density="0" rgba="0.6 0.8 0.9 1" mesh="right_finger2_link3" />
          <geom type="mesh" rgba="0.6 0.8 0.9 1" mesh="right_finger2_link3_collision" contype="1" conaffinity="1" />
          <body name="right_finger2_link4" pos="0 0 0.0295">
            <inertial pos="-0.000766056 -0.000179751 0.00770944" quat="0.998354 0.0103509 -0.0508894 0.0243386" mass="0.01718" diaginertia="1.58547e-06 1.49202e-06 4.21685e-07" />
            <joint name="right_finger2_joint4" pos="0 0 0" axis="0 1 0" range="-0.4644 1.5753" actuatorfrcrange="-0.217 0.217" />
            <geom type="mesh" contype="0" conaffinity="0" group="1" density="0" rgba="0.6 0.8 0.9 1" mesh="right_finger2_link4" />
            <geom type="mesh" rgba="0.6 0.8 0.9 1" mesh="right_finger2_link4_collision" contype="1" conaffinity="1" />
            <geom pos="-0.00105 0 0.0274" type="mesh" contype="0" conaffinity="0" group="1" density="0" rgba="0.6 0.8 0.9 1" mesh="right_finger2_tip_link" />
            <geom pos="-0.00105 0 0.0274" type="mesh" rgba="0.6 0.8 0.9 1" mesh="right_finger2_tip_link_collision" contype="1" conaffinity="1" />
          </body>
        </body>
      </body>
    </body>
    <body name="right_finger3_link1" pos="-0.01046 0.0074615 0.089544" quat="0.999048 -1.26848e-05 -0.0436192 0.000290547">
      <inertial pos="-0.0013291 3.4987e-09 0.00031994" quat="0.92388 0 0.382683 0" mass="0.0032" diaginertia="1.1e-07 7e-08 5e-08" />
      <joint name="right_finger3_joint1" pos="0 0 0" axis="0 1 0" range="-0.1719 1.5496" actuatorfrcrange="-0.6494 0.6494" />
      <geom type="mesh" contype="0" conaffinity="0" group="1" density="0" rgba="0.7 0.7 0.7 1" mesh="right_finger3_link1" />
      <geom type="mesh" rgba="0.7 0.7 0.7 1" mesh="right_finger3_link1_collision" contype="0" conaffinity="0" />
      <body name="right_finger3_link2" pos="0.0022 0 0.004">
        <inertial pos="-0.0061576 -4.1651e-07 0.020911" quat="0.70703 0.0104245 0.0104245 0.70703" mass="0.033" diaginertia="6.34e-06 6.31472e-06 8.85281e-07" />
        <joint name="right_finger3_joint2" pos="0 0 0" axis="-1 0 0" range="-0.4014 0.2996" actuatorfrcrange="-0.1827 0.1827" />
        <geom type="mesh" contype="0" conaffinity="0" group="1" density="0" rgba="0.9 0.8 0.6 1" mesh="right_finger3_link2" />
        <geom type="mesh" rgba="0.9 0.8 0.6 1" mesh="right_finger3_link2_collision" contype="2" conaffinity="2" />
        <body name="right_finger3_link3" pos="-0.00475 0 0.043618" quat="1 0 0 -0.000134305">
          <inertial pos="-0.0011214 4.331e-06 0.015763" quat="0.999892 0 -0.0146884 0" mass="0.0165" diaginertia="1.47088e-06 1.44e-06 4.49118e-07" />
          <joint name="right_finger3_joint3" pos="0 0 0" axis="0 1 0" range="-0.4632 1.5613" actuatorfrcrange="-0.2078 0.2078" />
          <geom type="mesh" contype="0" conaffinity="0" group="1" density="0" rgba="0.6 0.8 0.9 1" mesh="right_finger3_link3" />
          <geom type="mesh" rgba="0.6 0.8 0.9 1" mesh="right_finger3_link3_collision" contype="1" conaffinity="1" />
          <body name="right_finger3_link4" pos="0 0 0.0295">
            <inertial pos="-0.000766442 -0.000180017 0.00770944" quat="0.998352 0.0103722 -0.0509199 0.0243491" mass="0.01718" diaginertia="1.5855e-06 1.49202e-06 4.21669e-07" />
            <joint name="right_finger3_joint4" pos="0 0 0" axis="0 1 0" range="-0.4697 1.5702" actuatorfrcrange="-0.2018 0.2018" />
            <geom type="mesh" contype="0" conaffinity="0" group="1" density="0" rgba="0.6 0.8 0.9 1" mesh="right_finger3_link4" />
            <geom type="mesh" rgba="0.6 0.8 0.9 1" mesh="right_finger3_link4_collision" contype="1" conaffinity="1" />
            <geom pos="-0.0010491 0 0.0267" type="mesh" contype="0" conaffinity="0" group="1" density="0" rgba="0.6 0.8 0.9 1" mesh="right_finger3_tip_link" />
            <geom pos="-0.0010491 0 0.0267" type="mesh" rgba="0.6 0.8 0.9 1" mesh="right_finger3_tip_link_collision" contype="1" conaffinity="1" />
          </body>
        </body>
      </body>
    </body>
    <body name="right_finger4_link1" pos="-0.0076649 -0.013712 0.084429" quat="0.997789 0.0461019 -0.0405884 0.0254002">
      <inertial pos="-0.0013291 1.0048e-08 0.00031995" quat="0.92388 0 0.382683 0" mass="0.0032" diaginertia="1.1e-07 7e-08 5e-08" />
      <joint name="right_finger4_joint1" pos="0 0 0" axis="0 1 0" range="-0.1601 1.5534" actuatorfrcrange="-0.6389 0.6389" />
      <geom type="mesh" contype="0" conaffinity="0" group="1" density="0" rgba="0.7 0.7 0.7 1" mesh="right_finger4_link1" />
      <geom type="mesh" rgba="0.7 0.7 0.7 1" mesh="right_finger4_link1_collision" contype="0" conaffinity="0" />
      <body name="right_finger4_link2" pos="0.0022 0 0.004">
        <inertial pos="-0.0061576 -4.1601e-07 0.020911" quat="0.70703 0.0104245 0.0104245 0.70703" mass="0.033" diaginertia="6.34e-06 6.31472e-06 8.85281e-07" />
        <joint name="right_finger4_joint2" pos="0 0 0" axis="-1 0 0" range="-0.4134 0.3161" actuatorfrcrange="-0.1832 0.1832" />
        <geom type="mesh" contype="0" conaffinity="0" group="1" density="0" rgba="0.9 0.8 0.6 1" mesh="right_finger4_link2" />
        <geom type="mesh" rgba="0.9 0.8 0.6 1" mesh="right_finger4_link2_collision" contype="2" conaffinity="2" />
        <body name="right_finger4_link3" pos="-0.00475 0 0.043618" quat="1 0 0 -0.000134305">
          <inertial pos="-0.0011214 4.3494e-06 0.015763" quat="0.999892 0 -0.0146884 0" mass="0.0165" diaginertia="1.47088e-06 1.44e-06 4.49118e-07" />
          <joint name="right_finger4_joint3" pos="0 0 0" axis="0 1 0" range="-0.4782 1.5448" actuatorfrcrange="-0.2249 0.2249" />
          <geom type="mesh" contype="0" conaffinity="0" group="1" density="0" rgba="0.6 0.8 0.9 1" mesh="right_finger4_link3" />
          <geom type="mesh" rgba="0.6 0.8 0.9 1" mesh="right_finger4_link3_collision" contype="1" conaffinity="1" />
          <body name="right_finger4_link4" pos="0 0 0.0295">
            <inertial pos="-0.000766431 -0.000180689 0.00770952" quat="0.998349 0.0104237 -0.0509196 0.0244494" mass="0.01718" diaginertia="1.58554e-06 1.49205e-06 4.21684e-07" />
            <joint name="right_finger4_joint4" pos="0 0 0" axis="0 1 0" range="-0.4825 1.555" actuatorfrcrange="-0.2044 0.2044" />
            <geom type="mesh" contype="0" conaffinity="0" group="1" density="0" rgba="0.6 0.8 0.9 1" mesh="right_finger4_link4" />
            <geom type="mesh" rgba="0.6 0.8 0.9 1" mesh="right_finger4_link4_collision" contype="1" conaffinity="1" />
            <geom pos="-0.0010528 0 0.0267" type="mesh" contype="0" conaffinity="0" group="1" density="0" rgba="0.6 0.8 0.9 1" mesh="right_finger4_tip_link" />
            <geom pos="-0.0010528 0 0.0267" type="mesh" rgba="0.6 0.8 0.9 1" mesh="right_finger4_tip_link_collision" contype="1" conaffinity="1" />
          </body>
        </body>
      </body>
    </body>
    <body name="right_finger5_link1" pos="-0.0022687 -0.034001 0.074281" quat="0.99087 0.0993154 -0.0383256 0.0827347">
      <inertial pos="-0.0013291 1.7235e-08 0.00031997" quat="0.92388 0 0.382683 0" mass="0.0032" diaginertia="1.1e-07 7e-08 5e-08" />
      <joint name="right_finger5_joint1" pos="0 0 0" axis="0 1 0" range="-0.1674 1.5539" actuatorfrcrange="-0.6441 0.6441" />
      <geom type="mesh" contype="0" conaffinity="0" group="1" density="0" rgba="0.7 0.7 0.7 1" mesh="right_finger5_link1" />
      <geom type="mesh" rgba="0.7 0.7 0.7 1" mesh="right_finger5_link1_collision" contype="0" conaffinity="0" />
      <body name="right_finger5_link2" pos="0.0022 0 0.004">
        <inertial pos="-0.0061576 -4.1475e-07 0.020911" quat="0.70703 0.0104245 0.0104245 0.70703" mass="0.033" diaginertia="6.34e-06 6.31472e-06 8.85281e-07" />
        <joint name="right_finger5_joint2" pos="0 0 0" axis="-1 0 0" range="-0.4203 0.2931" actuatorfrcrange="-0.1798 0.1798" />
        <geom type="mesh" contype="0" conaffinity="0" group="1" density="0" rgba="0.9 0.8 0.6 1" mesh="right_finger5_link2" />
        <geom type="mesh" rgba="0.9 0.8 0.6 1" mesh="right_finger5_link2_collision" contype="2" conaffinity="2" />
        <body name="right_finger5_link3" pos="-0.00475 0 0.043618" quat="1 0 0 -0.000134305">
          <inertial pos="-0.0011214 4.3703e-06 0.015763" quat="0.999892 0 -0.0146884 0" mass="0.0165" diaginertia="1.47088e-06 1.44e-06 4.49118e-07" />
          <joint name="right_finger5_joint3" pos="0 0 0" axis="0 1 0" range="-0.4804 1.542" actuatorfrcrange="-0.2384 0.2384" />
          <geom type="mesh" contype="0" conaffinity="0" group="1" density="0" rgba="0.6 0.8 0.9 1" mesh="right_finger5_link3" />
          <geom type="mesh" rgba="0.6 0.8 0.9 1" mesh="right_finger5_link3_collision" contype="1" conaffinity="1" />
          <body name="right_finger5_link4" pos="0 0 0.0295">
            <inertial pos="-0.00076855 -0.000179174 0.00770942" quat="0.998351 0.0103138 -0.0510722 0.024077" mass="0.01718" diaginertia="1.58554e-06 1.49197e-06 4.21535e-07" />
            <joint name="right_finger5_joint4" pos="0 0 0" axis="0 1 0" range="-0.4705 1.5709" actuatorfrcrange="-0.1866 0.1866" />
            <geom type="mesh" contype="0" conaffinity="0" group="1" density="0" rgba="0.6 0.8 0.9 1" mesh="right_finger5_link4" />
            <geom type="mesh" rgba="0.6 0.8 0.9 1" mesh="right_finger5_link4_collision" contype="1" conaffinity="1" />
            <geom pos="-0.0010446 1.1308e-05 0.0267" type="mesh" contype="0" conaffinity="0" group="1" density="0" rgba="0.6 0.8 0.9 1" mesh="right_finger5_tip_link" />
            <geom pos="-0.0010446 1.1308e-05 0.0267" type="mesh" rgba="0.6 0.8 0.9 1" mesh="right_finger5_tip_link_collision" contype="1" conaffinity="1" />
          </body>
        </body>
      </body>
    </body>
  </worldbody>
    <actuator>
    <position name="right_finger1_joint1_actuator" joint="right_finger1_joint1" kp="0.5" ctrlrange="0.0368 1.6125" forcerange="-0.4452 0.4452" />
    <position name="right_finger1_joint2_actuator" joint="right_finger1_joint2" kp="0.5" ctrlrange="-0.1576 0.9312" forcerange="-0.4259 0.4259" />
    <position name="right_finger1_joint3_actuator" joint="right_finger1_joint3" kp="0.5" ctrlrange="-0.4638 1.5607" forcerange="-0.1888 0.1888" />
    <position name="right_finger1_joint4_actuator" joint="right_finger1_joint4" kp="0.5" ctrlrange="-0.4829 1.5451" forcerange="-0.1468 0.1468" />
    <position name="right_finger2_joint1_actuator" joint="right_finger2_joint1" kp="0.5" ctrlrange="-0.1611 1.5588" forcerange="-0.6188 0.6188" />
    <position name="right_finger2_joint2_actuator" joint="right_finger2_joint2" kp="0.5" ctrlrange="-0.4044 0.3054" forcerange="-0.1822 0.1822" />
    <position name="right_finger2_joint3_actuator" joint="right_finger2_joint3" kp="0.5" ctrlrange="-0.4714 1.5504" forcerange="-0.2251 0.2251" />
    <position name="right_finger2_joint4_actuator" joint="right_finger2_joint4" kp="0.5" ctrlrange="-0.4644 1.5753" forcerange="-0.217 0.217" />
    <position name="right_finger3_joint1_actuator" joint="right_finger3_joint1" kp="0.5" ctrlrange="-0.1719 1.5496" forcerange="-0.6494 0.6494" />
    <position name="right_finger3_joint2_actuator" joint="right_finger3_joint2" kp="0.5" ctrlrange="-0.4014 0.2996" forcerange="-0.1827 0.1827" />
    <position name="right_finger3_joint3_actuator" joint="right_finger3_joint3" kp="0.5" ctrlrange="-0.4632 1.5613" forcerange="-0.2078 0.2078" />
    <position name="right_finger3_joint4_actuator" joint="right_finger3_joint4" kp="0.5" ctrlrange="-0.4697 1.5702" forcerange="-0.2018 0.2018" />
    <position name="right_finger4_joint1_actuator" joint="right_finger4_joint1" kp="0.5" ctrlrange="-0.1601 1.5534" forcerange="-0.6389 0.6389" />
    <position name="right_finger4_joint2_actuator" joint="right_finger4_joint2" kp="0.5" ctrlrange="-0.4134 0.3161" forcerange="-0.1832 0.1832" />
    <position name="right_finger4_joint3_actuator" joint="right_finger4_joint3" kp="0.5" ctrlrange="-0.4782 1.5448" forcerange="-0.2249 0.2249" />
    <position name="right_finger4_joint4_actuator" joint="right_finger4_joint4" kp="0.5" ctrlrange="-0.4825 1.555" forcerange="-0.2044 0.2044" />
    <position name="right_finger5_joint1_actuator" joint="right_finger5_joint1" kp="0.5" ctrlrange="-0.1674 1.5539" forcerange="-0.6441 0.6441" />
    <position name="right_finger5_joint2_actuator" joint="right_finger5_joint2" kp="0.5" ctrlrange="-0.4203 0.2931" forcerange="-0.1798 0.1798" />
    <position name="right_finger5_joint3_actuator" joint="right_finger5_joint3" kp="0.5" ctrlrange="-0.4804 1.542" forcerange="-0.2384 0.2384" />
    <position name="right_finger5_joint4_actuator" joint="right_finger5_joint4" kp="0.5" ctrlrange="-0.4705 1.5709" forcerange="-0.1866 0.1866" />
  </actuator>
</mujoco>